<?xml version="1.0" ?>
<!-- =================================================================================== -->
<!-- |    This document was autogenerated by xacro from panda_arm_hand.urdf.xacro      | -->
<!-- |    EDITING THIS FILE BY HAND IS NOT RECOMMENDED                                 | -->
<!-- =================================================================================== -->
<robot name="panda" xmlns:xacro="http://www.ros.org/wiki/xacro">
  <link name="panda_link_0">
    <visual>
      <geometry>
        <mesh filename="meshes/visual/link0.stl"/>
      </geometry>
      <material name="panda_white">
        <color rgba="1. 1. 1. 1."/>
      </material>
    </visual>
    <collision>
      <geometry>
        <mesh filename="meshes/collision/link0.stl"/>
      </geometry>
      <material name="panda_white">
        <color rgba="1. 1. 1. 1."/>
      </material>
    </collision>
  </link>

  <link name="panda_pedestal">
    <visual>
      <origin rpy="1.57079632679 0 -1.57079632679" xyz="0.26 0.345 -0.91488"/>
      <geometry>
        <mesh filename="meshes/panda_pedestal/pedestal.STL"/>
      </geometry>
      <material name="darkgray">
        <color rgba=".2 .2 .2 1"/>
      </material>
    </visual>
    <collision>
      <origin rpy="0 0 0" xyz="-0.02 0 -0.29"/>
      <geometry>
        <cylinder length="0.62" radius="0.18"/>
      </geometry>
    </collision>
    <inertial>
      <origin rpy="0 0 0" xyz="0 0 -0.5"/>
      <mass value="60.86397744"/>
      <inertia ixx="5.0635929" ixy="0.00103417" ixz="0.80199628" iyy="6.08689388" iyz="0.00105311" izz="4.96191932"/>
    </inertial>
  </link>

  <joint name="panda_pedestal_fixed" type="fixed">
    <origin rpy="0 0 0" xyz="0.0 0.0 0.0"/>
    <parent link="panda_link_0"/>
    <child link="panda_pedestal"/>
  </joint>  

  <link name="panda_controller_box">
    <collision>
      <origin rpy="0 0 0" xyz="-0.325 0 -0.38"/>
      <geometry>
        <box size="0.22 0.4 0.53"/>
      </geometry>
    </collision>
  </link>

  <joint name="panda_controller_box_fixed" type="fixed">
    <origin rpy="0 0 0" xyz="0.0 0.0 0.0"/>
    <parent link="panda_link_0"/>
    <child link="panda_controller_box"/>
  </joint>

  <link name="panda_pedestal_feet">
    <collision>
      <origin rpy="0 0 0" xyz="-0.1225 0 -0.758"/>
      <geometry>
        <box size="0.77 0.7 0.31"/>
      </geometry>
    </collision>
  </link>

  <joint name="panda_pedestal_feet_fixed" type="fixed">
    <origin rpy="0 0 0" xyz="0.0 0.0 0.0"/>
    <parent link="panda_link_0"/>
    <child link="panda_pedestal_feet"/>
  </joint>
  
  <link name="panda_link_1">
    <visual>
      <geometry>
        <mesh filename="meshes/visual/link1.stl"/>
      </geometry>
      <material name="panda_white">
        <color rgba="1. 1. 1. 1."/>
      </material>
    </visual>
    <collision>
      <geometry>
        <mesh filename="meshes/collision/link1.stl"/>
      </geometry>
      <material name="panda_white">
        <color rgba="1. 1. 1. 1."/>
      </material>
    </collision>
  </link>

  <joint name="panda_joint1" type="revolute">
    <safety_controller k_position="100.0" k_velocity="40.0" soft_lower_limit="-2.8973" soft_upper_limit="2.8973"/>
    <origin rpy="0 0 0" xyz="0 0 0.333"/>
    <parent link="panda_link_0"/>
    <child link="panda_link_1"/>
    <axis xyz="0 0 1"/>
    <limit effort="87" lower="-2.9671" upper="2.9671" velocity="2.1750"/>
  </joint>
  <link name="panda_link_2">
    <visual>
      <geometry>
        <mesh filename="meshes/visual/link2.stl"/>
      </geometry>
      <material name="panda_white">
        <color rgba="1. 1. 1. 1."/>
      </material>
    </visual>
    <collision>
      <geometry>
        <mesh filename="meshes/collision/link2.stl"/>
      </geometry>
      <material name="panda_white">
        <color rgba="1. 1. 1. 1."/>
      </material>
    </collision>
  </link>
  <joint name="panda_joint2" type="revolute">
    <safety_controller k_position="100.0" k_velocity="40.0" soft_lower_limit="-1.7628" soft_upper_limit="1.7628"/>
    <origin rpy="-1.57079632679 0 0" xyz="0 0 0"/>
    <parent link="panda_link_1"/>
    <child link="panda_link_2"/>
    <axis xyz="0 0 1"/>
    <limit effort="87" lower="-1.8326" upper="1.8326" velocity="2.1750"/>
  </joint>
  <link name="panda_link_3">
    <visual>
      <geometry>
        <mesh filename="meshes/visual/link3.stl"/>
      </geometry>
      <material name="panda_white">
        <color rgba="1. 1. 1. 1."/>
      </material>
    </visual>
    <collision>
      <geometry>
        <mesh filename="meshes/collision/link3.stl"/>
      </geometry>
      <material name="panda_white">
        <color rgba="1. 1. 1. 1."/>
      </material>
    </collision>
  </link>
  <joint name="panda_joint3" type="revolute">
    <safety_controller k_position="100.0" k_velocity="40.0" soft_lower_limit="-2.8973" soft_upper_limit="2.8973"/>
    <origin rpy="1.57079632679 0 0" xyz="0 -0.316 0"/>
    <parent link="panda_link_2"/>
    <child link="panda_link_3"/>
    <axis xyz="0 0 1"/>
    <limit effort="87" lower="-2.9671" upper="2.9671" velocity="2.1750"/>
  </joint>
  <link name="panda_link_4">
    <visual>
      <geometry>
        <mesh filename="meshes/visual/link4.stl"/>
      </geometry>
      <material name="panda_white">
        <color rgba="1. 1. 1. 1."/>
      </material>
    </visual>
    <collision>
      <geometry>
        <mesh filename="meshes/collision/link4.stl"/>
      </geometry>
      <material name="panda_white">
        <color rgba="1. 1. 1. 1."/>
      </material>
    </collision>
  </link>
  <joint name="panda_joint4" type="revolute">
    <safety_controller k_position="100.0" k_velocity="40.0" soft_lower_limit="-3.0718" soft_upper_limit="-0.0698"/>
    <origin rpy="1.57079632679 0 0" xyz="0.0825 0 0"/>
    <parent link="panda_link_3"/>
    <child link="panda_link_4"/>
    <axis xyz="0 0 1"/>
    <limit effort="87" lower="-3.1416" upper="0.0" velocity="2.1750"/>
  </joint>
  <link name="panda_link_5">
    <visual>
      <geometry>
        <mesh filename="meshes/visual/link5.stl"/>
      </geometry>
      <material name="panda_white">
        <color rgba="1. 1. 1. 1."/>
      </material>
    </visual>
    <collision>
      <geometry>
        <mesh filename="meshes/collision/link5.stl"/>
      </geometry>
      <material name="panda_white">
        <color rgba="1. 1. 1. 1."/>
      </material>
    </collision>
  </link>
  <joint name="panda_joint5" type="revolute">
    <safety_controller k_position="100.0" k_velocity="40.0" soft_lower_limit="-2.8973" soft_upper_limit="2.8973"/>
    <origin rpy="-1.57079632679 0 0" xyz="-0.0825 0.384 0"/>
    <parent link="panda_link_4"/>
    <child link="panda_link_5"/>
    <axis xyz="0 0 1"/>
    <limit effort="12" lower="-2.9671" upper="2.9671" velocity="2.6100"/>
  </joint>
  <link name="panda_link_6">
    <visual>
      <geometry>
        <mesh filename="meshes/visual/link6.stl"/>
      </geometry>
      <material name="panda_white">
        <color rgba="1. 1. 1. 1."/>
      </material>
    </visual>
    <collision>
      <geometry>
        <mesh filename="meshes/collision/link6.stl"/>
      </geometry>
      <material name="panda_white">
        <color rgba="1. 1. 1. 1."/>
      </material>
    </collision>
  </link>
  <joint name="panda_joint6" type="revolute">
    <safety_controller k_position="100.0" k_velocity="40.0" soft_lower_limit="-0.0175" soft_upper_limit="3.7525"/>
    <origin rpy="1.57079632679 0 0" xyz="0 0 0"/>
    <parent link="panda_link_5"/>
    <child link="panda_link_6"/>
    <axis xyz="0 0 1"/>
    <limit effort="12" lower="-0.0873" upper="3.8223" velocity="2.6100"/>
  </joint>
  <link name="panda_link_7">
    <visual>
      <geometry>
        <mesh filename="meshes/visual/link7.stl"/>
      </geometry>
      <material name="panda_white">
        <color rgba="1. 1. 1. 1."/>
      </material>
    </visual>
    <collision>
      <geometry>
        <mesh filename="meshes/collision/link7.stl"/>
      </geometry>
      <material name="panda_white">
        <color rgba="1. 1. 1. 1."/>
      </material>
    </collision>
  </link>
  <joint name="panda_joint7" type="revolute">
    <safety_controller k_position="100.0" k_velocity="40.0" soft_lower_limit="-2.8973" soft_upper_limit="2.8973"/>
    <origin rpy="1.57079632679 0 0" xyz="0.088 0 0"/>
    <parent link="panda_link_6"/>
    <child link="panda_link_7"/>
    <axis xyz="0 0 1"/>
    <limit effort="12" lower="-2.9671" upper="2.9671" velocity="2.6100"/>
  </joint>

  <link name="right_hand"/>
  <joint name="right_hand_fixed" type="fixed">
    <origin rpy="0 0 -0.7858908" xyz="0 0 0.1065"/>
    <parent link="panda_link_7"/>
    <child link="right_hand"/>
  </joint>

  <link name="right_gripper">
    <visual>
      <origin rpy="0 0 1.5707963" xyz="0 0 0"/>
      <geometry>
          <mesh filename="meshes/visual/hand.stl"/>
      </geometry>
      <material name="panda_white">
        <color rgba="1. 1. 1. 1."/>
      </material>
    </visual>
    <collision>
    <origin rpy="0 0 1.5707963" xyz="0 0 0"/>
      <geometry>
        <mesh filename="meshes/collision/hand.stl"/>
      </geometry>
      <material name="panda_white">
        <color rgba="1. 1. 1. 1."/>
      </material>
    </collision>
  </link>

  <joint name="panda_right_gripper_fixed" type="fixed">
    <origin rpy="0 0 -1.5707963" xyz="0 0 0"/>
    <parent link="right_hand"/>
    <child link="right_gripper"/>
    <axis xyz="0 0 0"/>
  </joint>

  <link name="tcp"/>
  <joint name="panda_eef_fixed" type="fixed">
    <origin rpy="0 0 0" xyz="0 0 0.097"/>
    <parent link="right_hand"/>
    <child link="tcp"/>
  </joint>

  <link name="leftfinger">
    <visual>
    <origin rpy="0 0 0" xyz="0 0 0"/>
      <geometry>
          <mesh filename="meshes/visual/finger.stl"/>
      </geometry>
      <material name="panda_black">
        <color rgba=".2 .2 .2 1"/>
      </material>
    </visual>
    <collision>
      <geometry>
        <mesh filename="meshes/collision/finger.stl"/>
      </geometry>
      <material name="panda_black">
        <color rgba=".2 .2 .2 1"/>
      </material>
    </collision>
  </link>

  <link name="rightfinger">
    <visual>
      <origin rpy="0 0 3.1415927" xyz="0 0 0"/>
      <geometry>
          <mesh filename="meshes/visual/finger.stl"/>
      </geometry>
      <material name="panda_black">
        <color rgba=".2 .2 .2 1"/>
      </material>
    </visual>
    <collision>
      <origin rpy="0 0 3.1415927" xyz="0 0 0"/>
      <geometry>
        <mesh filename="meshes/collision/finger.stl"/>
      </geometry>
      <material name="panda_black">
        <color rgba=".2 .2 .2 1"/>
      </material>
    </collision>
  </link>

  <joint name="panda_finger_joint1" type="prismatic">
    <parent link="right_gripper"/>
    <child link="leftfinger"/>
    <origin rpy="0 0 1.5707963" xyz="-0.04 0 0.0524"/>
    <axis xyz="0 1 0"/>
    <limit effort="20" lower="0.0" upper="0.04" velocity="0.2"/>
  </joint>

  <joint name="panda_finger_joint2" type="prismatic">
    <parent link="right_gripper"/>
    <child link="rightfinger"/>
    <origin rpy="0 0 1.5707963" xyz="0.04 0 0.0524"/>
    <axis xyz="0 1 0"/>
    <limit effort="20" lower="0.0" upper="0.04" velocity="0.2"/>
  </joint>


</robot>