<?xml version="1.0" ?>
<!-- =================================================================================== -->
<!-- |    This document was autogenerated by xacro from ur5e_joint_limited_box_robot_robotiq3.urdf.xacro | -->
<!-- |    EDITING THIS FILE BY HAND IS NOT RECOMMENDED                                 | -->
<!-- =================================================================================== -->
<robot name="ur5e" xmlns:xacro="http://ros.org/wiki/xacro">
  <link name="ur5e_base_link">
    <visual>
      <origin xyz="0 0 0" rpy="1.5707963 0 0"/>
      <geometry>
        <mesh filename="meshes/visual/base_vis.stl"/>
      </geometry>
      <material name="LightGrey">
        <color rgba="0.7 0.7 0.7 1"/>
      </material>
    </visual>
    <collision>
      <geometry>
        <mesh filename="meshes/collision/base.stl"/>
      </geometry>
    </collision>
    <inertial>
      <mass value="4.0"/>
      <origin rpy="0 0 0" xyz="0.0 0.0 0.0"/>
      <inertia ixx="0.00443333156" ixy="0.0" ixz="0.0" iyy="0.00443333156" iyz="0.0" izz="0.0072"/>
    </inertial>
  </link>

  <link name="ur5e_pedestal">
    <visual>
      <origin rpy="1.57079632679 0 -1.57079632679" xyz="0.26 0.345 -0.91488"/>
      <geometry>
        <mesh filename="meshes/ur5e_pedestal/pedestal.STL"/>
      </geometry>
      <material name="darkgray">
        <color rgba=".2 .2 .2 1"/>
      </material>
    </visual>
    <collision>
      <origin rpy="0 0 0" xyz="-0.02 0 -0.29"/>
      <geometry>
        <cylinder length="0.62" radius="0.18"/>
      </geometry>
    </collision>
    <inertial>
      <origin rpy="0 0 0" xyz="0 0 -0.5"/>
      <mass value="60.86397744"/>
      <inertia ixx="5.0635929" ixy="0.00103417" ixz="0.80199628" iyy="6.08689388" iyz="0.00105311" izz="4.96191932"/>
    </inertial>
  </link>

  <joint name="ur5e_pedestal_fixed" type="fixed">
    <origin rpy="0 0 0" xyz="0.0 0.0 0.0"/>
    <parent link="ur5e_base_link"/>
    <child link="ur5e_pedestal"/>
  </joint>  

  <link name="ur5e_controller_box">
    <collision>
      <origin rpy="0 0 0" xyz="-0.325 0 -0.38"/>
      <geometry>
        <box size="0.22 0.4 0.53"/>
      </geometry>
    </collision>
  </link>

  <joint name="ur5e_controller_box_fixed" type="fixed">
    <origin rpy="0 0 0" xyz="0.0 0.0 0.0"/>
    <parent link="ur5e_base_link"/>
    <child link="ur5e_controller_box"/>
  </joint>

  <link name="ur5e_pedestal_feet">
    <collision>
      <origin rpy="0 0 0" xyz="-0.1225 0 -0.758"/>
      <geometry>
        <box size="0.77 0.7 0.31"/>
      </geometry>
    </collision>
  </link>

  <joint name="ur5e_pedestal_feet_fixed" type="fixed">
    <origin rpy="0 0 0" xyz="0.0 0.0 0.0"/>
    <parent link="ur5e_base_link"/>
    <child link="ur5e_pedestal_feet"/>
  </joint>
  
  <joint name="shoulder_pan_joint" type="revolute">
    <parent link="ur5e_base_link"/>
    <child link="ur5e_shoulder_link"/>
    <origin rpy="0.0 0.0 0.0" xyz="0.0 0.0 0.163"/>
    <axis xyz="0 0 1"/>
    <limit effort="150.0" lower="-3.14159265" upper="3.14159265" velocity="3.15"/>
    <dynamics damping="0.0" friction="0.0"/>
  </joint>
  <link name="ur5e_shoulder_link">
    <visual>
    <origin xyz="0 0 0" rpy="1.5707963 0 0"/>
      <geometry>
        <mesh filename="meshes/visual/shoulder_vis.stl"/>
      </geometry>
      <material name="LightGrey">
        <color rgba="0.7 0.7 0.7 1.0"/>
      </material>
    </visual>
    <collision>
      <geometry>
        <mesh filename="meshes/collision/shoulder.stl"/>
      </geometry>
    </collision>
    <inertial>
      <mass value="3.7"/>
      <origin rpy="0 0 0" xyz="0.0 0.0 0.0"/>
      <inertia ixx="0.010267495893" ixy="0.0" ixz="0.0" iyy="0.010267495893" iyz="0.0" izz="0.00666"/>
    </inertial>
  </link>
  <joint name="shoulder_lift_joint" type="revolute">
    <parent link="ur5e_shoulder_link"/>
    <child link="ur5e_upper_arm_link"/>
    <origin rpy="0.0 1.570796325 0.0" xyz="0.0 0.138 0.0"/>
    <axis xyz="0 1 0"/>
    <limit effort="150.0" lower="-3.14159265" upper="-0.9" velocity="3.15"/>
    <!-- <limit effort="150.0" lower="-3.14159265" upper="-0.8" velocity="3.15"/> -->
    <dynamics damping="0.0" friction="0.0"/>
  </joint>
  <link name="ur5e_upper_arm_link">
    <visual>
      <origin xyz="0 0 0" rpy="1.5707963 0 0"/>
      <geometry>
        <mesh filename="meshes/visual/upperarm_vis.stl"/>
      </geometry>
      <material name="LightGrey">
        <color rgba="0.7 0.7 0.7 1.0"/>
      </material>
    </visual>
    <collision>
      <geometry>
        <mesh filename="meshes/collision/upperarm.stl"/>
      </geometry>
    </collision>
    <inertial>
      <mass value="8.393"/>
      <origin rpy="0 0 0" xyz="0.0 0.0 0.28"/>
      <inertia ixx="0.22689067591" ixy="0.0" ixz="0.0" iyy="0.22689067591" iyz="0.0" izz="0.0151074"/>
    </inertial>
  </link>
  <joint name="elbow_joint" type="revolute">
    <parent link="ur5e_upper_arm_link"/>
    <child link="ur5e_forearm_link"/>
    <origin rpy="0.0 0.0 0.0" xyz="0.0 -0.131 0.425"/>
    <axis xyz="0 1 0"/>
    <limit effort="150.0" lower="-3.14159265" upper="3.14159265" velocity="3.15"/>
    <dynamics damping="0.0" friction="0.0"/>
  </joint>
  <link name="ur5e_forearm_link">
    <visual>
      <origin xyz="0 0 0" rpy="1.5707963 0 0"/>
      <geometry>
        <mesh filename="meshes/visual/forearm_vis.stl"/>
      </geometry>
      <material name="LightGrey">
        <color rgba="0.7 0.7 0.7 1.0"/>
      </material>
    </visual>
    <collision>
      <geometry>
        <mesh filename="meshes/collision/forearm.stl"/>
      </geometry>
    </collision>
    <inertial>
      <mass value="2.275"/>
      <origin rpy="0 0 0" xyz="0.0 0.0 0.25"/>
      <inertia ixx="0.049443313556" ixy="0.0" ixz="0.0" iyy="0.049443313556" iyz="0.0" izz="0.004095"/>
    </inertial>
  </link>
  <joint name="wrist_1_joint" type="revolute">
    <parent link="ur5e_forearm_link"/>
    <child link="ur5e_wrist_1_link"/>
    <origin rpy="0.0 1.570796325 0.0" xyz="0 0 0.392"/>
    <axis xyz="0 1 0"/>
    <limit effort="28.0" lower="-3.14159265" upper="3.14159265" velocity="3.2"/>
    <dynamics damping="0.0" friction="0.0"/>
  </joint>
  <link name="ur5e_wrist_1_link">
    <visual>
      <origin xyz="0 0 0" rpy="1.5707963 0 0"/>
      <geometry>
        <mesh filename="meshes/visual/wrist1_vis.stl"/>
      </geometry>
      <material name="LightGrey">
        <color rgba="0.7 0.7 0.7 1.0"/>
      </material>
    </visual>
    <collision>
      <geometry>
        <mesh filename="meshes/collision/wrist1.stl"/>
      </geometry>
    </collision>
    <inertial>
      <mass value="1.219"/>
      <origin rpy="0 0 0" xyz="0.0 0.0 0.0"/>
      <inertia ixx="0.111172755531" ixy="0.0" ixz="0.0" iyy="0.111172755531" iyz="0.0" izz="0.21942"/>
    </inertial>
  </link>
  <joint name="wrist_2_joint" type="revolute">
    <parent link="ur5e_wrist_1_link"/>
    <child link="ur5e_wrist_2_link"/>
    <origin rpy="0.0 0.0 0.0" xyz="0.0 0.127 0.0"/>
    <axis xyz="0 0 1"/>
    <limit effort="28.0" lower="-3.14159265" upper="3.14159265" velocity="3.2"/>
    <dynamics damping="0.0" friction="0.0"/>
  </joint>
  <link name="ur5e_wrist_2_link">
    <visual>
      <origin xyz="0 0 0" rpy="1.5707963 0 0"/>
      <geometry>
        <mesh filename="meshes/visual/wrist2_vis.stl"/>
      </geometry>
      <material name="LightGrey">
        <color rgba="0.7 0.7 0.7 1.0"/>
      </material>
    </visual>
    <collision>
      <geometry>
        <mesh filename="meshes/collision/wrist2.stl"/>
      </geometry>
    </collision>
    <inertial>
      <mass value="1.219"/>
      <origin rpy="0 0 0" xyz="0.0 0.0 0.0"/>
      <inertia ixx="0.111172755531" ixy="0.0" ixz="0.0" iyy="0.111172755531" iyz="0.0" izz="0.21942"/>
    </inertial>
  </link>
  <joint name="wrist_3_joint" type="revolute">
    <parent link="ur5e_wrist_2_link"/>
    <child link="ur5e_wrist_3_link"/>
    <origin rpy="0.0 0.0 0.0" xyz="0 0 0.1"/>
    <axis xyz="0 1 0"/>
    <limit effort="28.0" lower="-3.14159265" upper="3.14159265" velocity="3.2"/>
    <dynamics damping="0.0" friction="0.0"/>
  </joint>
  <link name="ur5e_wrist_3_link">
    <visual>
      <origin xyz="0 0 0" rpy="1.5707963 0 0"/>
      <geometry>
        <mesh filename="meshes/visual/wrist3_vis.stl"/>
      </geometry>
      <material name="LightGrey">
        <color rgba="0.7 0.7 0.7 1.0"/>
      </material>
    </visual>
    <collision>
      <geometry>
        <mesh filename="meshes/collision/wrist3.stl"/>
      </geometry>
    </collision>
    <inertial>
      <mass value="0.1879"/>
      <origin rpy="0 0 0" xyz="0.0 0.0 0.0"/>
      <inertia ixx="0.0171364731454" ixy="0.0" ixz="0.0" iyy="0.0171364731454" iyz="0.0" izz="0.033822"/>
    </inertial>
  </link>
  <joint name="ee_fixed_joint" type="fixed">
    <parent link="ur5e_wrist_3_link"/>
    <child link="ur5e_right_hand"/>
    <origin rpy="-1.5707963 0.0 0" xyz="0 0.098 0"/>
  </joint>
  <link name="ur5e_right_hand">
    <collision>
      <geometry>
        <box size="0.01 0.01 0.01"/>
      </geometry>
      <origin rpy="0 0 0" xyz="-0.01 0 0"/>
    </collision>
  </link>

    <link name="right_gripper">
        <inertial>
            <origin xyz="8.625E-08 -4.6583E-06 0.03145" rpy="0 0 0" />
            <mass value="0.22652" />
            <inertia ixx="0.00020005" ixy="-4.2442E-10" ixz="-2.9069E-10" iyy="0.00017832" iyz="-3.4402E-08" izz="0.00013478" />
        </inertial>
        <visual>
        <origin xyz="0 0 -0.061525" quat="0 0.707388 -0.706825 0" />
        <geometry>
            <mesh filename="meshes/visual/robotiq_arg2f_base_link.stl" />
        </geometry>
        <material name="">
            <color rgba="0.1 0.1 0.1 1" />
        </material>
        </visual>
        <collision>
        <origin xyz="0 0 -0.061525" quat="0 0.707388 -0.706825 0" />
        <geometry>
            <mesh filename="meshes/collision/robotiq_arg2f_base_link.stl" />
        </geometry>
        </collision>
    </link>

    <joint name="right_gripper_fixed" type="fixed">
        <origin quat="0 -0.707105 0.707108 0 " xyz="0 0 -0.0625"/>
        <parent link="ur5e_right_hand"/>
        <child link="right_gripper"/>
        <axis xyz="0 0 0"/>
    </joint>

    <link name="tcp"/>
    <joint name="doosan_eef_fixed" type="fixed">
        <origin quat="1 0 0 0" xyz="0 0 0.2075"/>
        <parent link="ur5e_right_hand"/>
        <child link="tcp"/>
    </joint>

    <joint name="finger_joint" type="fixed">
        <origin xyz="0.030601 2.43684e-05 -0.11643" quat="-0.64507 0.290316 -0.290085 0.644556"/>
        <parent link="right_gripper" />
        <child link="left_outer_knuckle" />
        <axis xyz="-1 0 0" />
        <limit lower="0" upper="0.7" velocity="2.0" effort="1000" />
    </joint>

    <joint name="right_outer_knuckle_joint" type="fixed">
        <origin xyz="-0.030601 -2.43684e-05 -0.11643" quat="0.644556 -0.290085 -0.290316 0.64507"/>
        <parent link="right_gripper" />
        <child link="right_outer_knuckle" />
        <axis xyz="1 0 0" />
        <limit lower="-0.725" upper="0.725" velocity="2.0" effort="1000" />
        <mimic joint="finger_joint" multiplier="-1" offset="0" />
    </joint>

    <link name="right_outer_knuckle">
        <inertial>
            <origin xyz="-0.000200000000003065 0.0199435877845359 0.0292245259211331" rpy="0 0 0" />
            <mass value="0.00853198276973456" />
            <inertia
                ixx="2.89328108496468E-06"
                ixy="-1.57935047237397E-19"
                ixz="-1.93980378593255E-19"
                iyy="1.86719750325683E-06"
                iyz="-1.21858577871576E-06"
                izz="1.21905238907251E-06" />
        </inertial>
        <visual>
            <origin xyz="0 0 0" rpy="0 0 0" />
            <geometry>
                <mesh filename="meshes/visual/robotiq_arg2f_140_outer_knuckle.stl" />
            </geometry>
            <material name="">
                <color rgba="0.792156862745098 0.819607843137255 0.933333333333333 1" />
            </material>
        </visual>
        <collision>
            <origin xyz="0 0 0" rpy="0 0 0" />
            <geometry>
                <mesh filename="meshes/collision/robotiq_arg2f_140_outer_knuckle.stl" />
            </geometry>
        </collision>
    </link>

    <link name="right_outer_finger">
        <inertial>
            <origin xyz="0.00030115855001899 0.0373907951953854 -0.0208027427000385" rpy="0 0 0" />
            <mass value="0.022614240507152" />
            <inertia
                ixx="1.52518312458174E-05"
                ixy="9.76583423954399E-10"
                ixz="-5.43838577022588E-10"
                iyy="6.17694243867776E-06"
                iyz="6.78636130740228E-06"
                izz="1.16494917907219E-05" />
        </inertial>
        <visual>
            <origin xyz="0 0 0" rpy="0 0 0" />
            <geometry>
                <mesh filename="meshes/visual/robotiq_arg2f_140_outer_finger.stl" />
            </geometry>
            <material name="">
                <color rgba="0.1 0.1 0.1 1" />
            </material>
        </visual>
        <collision>
            <origin xyz="0 0 0" rpy="0 0 0" />
            <geometry>
            <mesh filename="meshes/collision/robotiq_arg2f_140_outer_finger.stl" />
            </geometry>
        </collision>
    </link>

    <link name="right_inner_knuckle">
        <inertial>
            <origin xyz="0.000123011831763771 0.0507850843201817 0.00103968640075166" rpy="0 0 0" />
            <mass value="0.0271177346495152" />
            <inertia
                ixx="2.61910379223783E-05"
                ixy="-2.43616858946494E-07"
                ixz="-6.37789906117123E-09"
                iyy="2.8270243746167E-06"
                iyz="-5.37200748039765E-07"
                izz="2.83695868220296E-05" />
        </inertial>
        <visual>
            <origin xyz="0 0 0" rpy="0 0 0" />
            <geometry>
            <mesh filename="meshes/visual/robotiq_arg2f_140_inner_knuckle.stl" />
            </geometry>
            <material name="">
            <color rgba="0.1 0.1 0.1 1" />
            </material>
        </visual>
        <collision>
            <origin xyz="0 0 0" rpy="0 0 0" />
            <geometry>
            <mesh filename="meshes/collision/robotiq_arg2f_140_inner_knuckle.stl" />
            </geometry>
        </collision>
    </link>

    <link name="right_inner_finger">
        <inertial>
            <origin xyz="0.000299999999999317 0.0160078233491243 -0.0136945669206257" rpy="0 0 0" />
            <mass value="0.0104003125914103" />
            <inertia
                ixx="2.71909453810972E-06"
                ixy="1.35402465472579E-21"
                ixz="-7.1817349065269E-22"
                iyy="7.69100314106116E-07"
                iyz="6.74715432769696E-07"
                izz="2.30315190420171E-06" />
        </inertial>
        <visual>
            <origin xyz="0 0 0" rpy="0 0 0" />
            <geometry>
            <mesh filename="meshes/visual/robotiq_arg2f_140_inner_finger.stl" />
            </geometry>
            <material name="">
            <color rgba="0.1 0.1 0.1 1" />
            </material>
        </visual>
        <collision>
            <origin xyz="0 0 0" rpy="0 0 0" />
            <geometry>
            <mesh filename="meshes/collision/robotiq_arg2f_140_inner_finger.stl" />
            </geometry>
        </collision>
    </link>

    <link name="right_inner_finger_pad">
        <visual>
            <origin xyz="0 0 0" rpy="0 0 0" />
            <geometry>
            <box size="0.027 0.065 0.0075"/>
            </geometry>
            <material name="">
            <color rgba="0.9 0.9 0.9 1" />
            </material>
        </visual>
        <collision>
            <origin xyz="0 0 0" rpy="0 0 0" />
            <geometry>
            <box size="0.03 0.07 0.0075"/>
            </geometry>
            <material name="">
            <color rgba="0.9 0.0 0.0 1" />
            </material>
        </collision>
    </link>

    <joint name="right_outer_finger_joint" type="fixed">
        <origin xyz="0 0.01821998610742 0.0260018192872234" rpy="0 0 0" />
        <parent link="right_outer_knuckle" />
        <child link="right_outer_finger" />
        <axis xyz="1 0 0" />
    </joint>

    <joint name="right_inner_knuckle_joint" type="fixed">
        <origin xyz="-0.0127 -1.01133e-05 -0.122945" quat="-0.644556 0.290085 0.290316 -0.64507" />
        <parent link="right_gripper" />
        <child link="right_inner_knuckle" />
        <axis xyz="1 0 0" />
        <limit lower="-0.8757" upper="0.8757" velocity="2.0" effort="1000" />
        <mimic joint="finger_joint" multiplier="-1" offset="0" />
    </joint>

    <joint name="right_inner_finger_joint" type="fixed">
        <origin xyz="0 0.0999754 -0.00221853" quat="0.935013 -0.354613 0 0" />
        <parent link="right_outer_finger" />
        <child link="right_inner_finger" />
        <axis xyz="1 0 0" />
        <limit lower="-0.8757" upper="0.8757" velocity="2.0" effort="1000" />
        <mimic joint="finger_joint" multiplier="1" offset="0" />
    </joint>

    <joint name="right_inner_finger_pad_joint" type="fixed">
        <origin xyz="0 0.0457554 -0.0272203" rpy="0 0 0" />
        <parent link="right_inner_finger" />
        <child link="right_inner_finger_pad" />
        <axis xyz="0 0 1" />
    </joint>

    <link name="left_outer_knuckle">
        <inertial>
            <origin xyz="-0.000200000000003065 0.0199435877845359 0.0292245259211331" rpy="0 0 0" />
            <mass value="0.00853198276973456" />
            <inertia
                ixx="2.89328108496468E-06"
                ixy="-1.57935047237397E-19"
                ixz="-1.93980378593255E-19"
                iyy="1.86719750325683E-06"
                iyz="-1.21858577871576E-06"
                izz="1.21905238907251E-06" />
        </inertial>
        <visual>
            <origin xyz="0 0 0" rpy="0 0 0" />
            <geometry>
                <mesh filename="meshes/visual/robotiq_arg2f_140_outer_knuckle.stl" />
            </geometry>
            <material name="">
                <color rgba="0.792156862745098 0.819607843137255 0.933333333333333 1" />
            </material>
        </visual>
        <collision>
            <origin xyz="0 0 0" rpy="0 0 0" />
            <geometry>
                <mesh filename="meshes/collision/robotiq_arg2f_140_outer_knuckle.stl" />
            </geometry>
        </collision>
    </link>

    <link name="left_outer_finger">
        <inertial>
            <origin xyz="0.00030115855001899 0.0373907951953854 -0.0208027427000385" rpy="0 0 0" />
            <mass value="0.022614240507152" />
            <inertia
                ixx="1.52518312458174E-05"
                ixy="9.76583423954399E-10"
                ixz="-5.43838577022588E-10"
                iyy="6.17694243867776E-06"
                iyz="6.78636130740228E-06"
                izz="1.16494917907219E-05" />
        </inertial>
        <visual>
            <origin xyz="0 0 0" rpy="0 0 0" />
            <geometry>
                <mesh filename="meshes/visual/robotiq_arg2f_140_outer_finger.stl" />
            </geometry>
            <material name="">
                <color rgba="0.1 0.1 0.1 1" />
            </material>
        </visual>
        <collision>
            <origin xyz="0 0 0" rpy="0 0 0" />
            <geometry>
            <mesh filename="meshes/collision/robotiq_arg2f_140_outer_finger.stl" />
            </geometry>
        </collision>
    </link>

    <link name="left_inner_knuckle">
        <inertial>
            <origin xyz="0.000123011831763771 0.0507850843201817 0.00103968640075166" rpy="0 0 0" />
            <mass value="0.0271177346495152" />
            <inertia
                ixx="2.61910379223783E-05"
                ixy="-2.43616858946494E-07"
                ixz="-6.37789906117123E-09"
                iyy="2.8270243746167E-06"
                iyz="-5.37200748039765E-07"
                izz="2.83695868220296E-05" />
        </inertial>
        <visual>
            <origin xyz="0 0 0" rpy="0 0 0" />
            <geometry>
            <mesh filename="meshes/visual/robotiq_arg2f_140_inner_knuckle.stl" />
            </geometry>
            <material name="">
            <color rgba="0.1 0.1 0.1 1" />
            </material>
        </visual>
        <collision>
            <origin xyz="0 0 0" rpy="0 0 0" />
            <geometry>
            <mesh filename="meshes/collision/robotiq_arg2f_140_inner_knuckle.stl" />
            </geometry>
        </collision>
    </link>

    <link name="left_inner_finger">
        <inertial>
            <origin xyz="0.000299999999999317 0.0160078233491243 -0.0136945669206257" rpy="0 0 0" />
            <mass value="0.0104003125914103" />
            <inertia
                ixx="2.71909453810972E-06"
                ixy="1.35402465472579E-21"
                ixz="-7.1817349065269E-22"
                iyy="7.69100314106116E-07"
                iyz="6.74715432769696E-07"
                izz="2.30315190420171E-06" />
        </inertial>
        <visual>
            <origin xyz="0 0 0" rpy="0 0 0" />
            <geometry>
            <mesh filename="meshes/visual/robotiq_arg2f_140_inner_finger.stl" />
            </geometry>
            <material name="">
            <color rgba="0.1 0.1 0.1 1" />
            </material>
        </visual>
        <collision>
            <origin xyz="0 0 0" rpy="0 0 0" />
            <geometry>
            <mesh filename="meshes/collision/robotiq_arg2f_140_inner_finger.stl" />
            </geometry>
        </collision>
    </link>

    <link name="left_inner_finger_pad">
        <visual>
            <origin xyz="0 0 0" rpy="0 0 0" />
            <geometry>
            <box size="0.027 0.065 0.0075"/>
            </geometry>
            <material name="">
            <color rgba="0.9 0.9 0.9 1" />
            </material>
        </visual>
        <collision>
            <origin xyz="0 0 0" rpy="0 0 0" />
            <geometry>
            <box size="0.03 0.07 0.0075"/>
            </geometry>
            <material name="">
            <color rgba="0.9 0.0 0.0 1" />
            </material>
        </collision>
    </link>

    <joint name="left_outer_finger_joint" type="fixed">
        <origin xyz="0 0.01821998610742 0.0260018192872234" rpy="0 0 0" />
        <parent link="left_outer_knuckle" />
        <child link="left_outer_finger" />
        <axis xyz="1 0 0" />
    </joint>

    <joint name="left_inner_knuckle_joint" type="fixed">
        <origin xyz="0.0127 1.01133e-05 -0.122945" quat="-0.64507 0.290316 -0.290085 0.644556"/>
        <parent link="right_gripper" />
        <child link="left_inner_knuckle" />
        <axis xyz="1 0 0" />
        <limit lower="-0.8757" upper="0.8757" velocity="2.0" effort="1000" />
        <mimic joint="finger_joint" multiplier="-1" offset="0" />
    </joint>

    <joint name="left_inner_finger_joint" type="fixed">
        <origin xyz="0 0.0999754 -0.00221853" quat="0.935013 -0.354613 0 0"/>
        <parent link="left_outer_finger" />
        <child link="left_inner_finger" />
        <axis xyz="1 0 0" />
        <limit lower="-0.8757" upper="0.8757" velocity="2.0" effort="1000" />
        <mimic joint="finger_joint" multiplier="1" offset="0" />
    </joint>

    <joint name="left_inner_finger_pad_joint" type="fixed">
        <origin xyz="0 0.0457554 -0.0272203" rpy="0 0 0" />
        <parent link="left_inner_finger" />
        <child link="left_inner_finger_pad" />
        <axis xyz="0 0 1" />
    </joint>

</robot>

