<?xml version="1.0"?>

<robot name="doosan" xmlns:xacro="http://www.ros.org/wiki/xacro">
    <link name="base_0">
        <inertial>
            <mass value="3.635"/>
            <origin xyz="4e-06   -0.001016     0.08181"/>
            <inertia ixx="0.02216" ixy="5.8001e-06" ixz="6.1941e-06" iyy="0.024835"
                iyz="-5.3034e-05"
                izz="0.021063"/>
            </inertial>
        <visual>
            <origin rpy="0 0 0" xyz="0 0 0" />
            <geometry>
                <mesh filename="meshes/a0912_blue/A0912_0_0.stl" scale="0.001 0.001 0.001" />
            </geometry>
			<material name="dr_gray">
				<color rgba="0.490 0.490 0.486 1.0"/>
			</material>
        </visual>
    </link>

  	<link name="doosan_pedestal">
    	<visual>
      		<origin rpy="1.57079632679 0 -1.57079632679" xyz="0.26 0.345 -0.91488"/>
      		<geometry>
        		<mesh filename="meshes/doosan_pedestal/pedestal.STL"/>
      		</geometry>
      		<material name="darkgray">
        		<color rgba=".2 .2 .2 1"/>
      		</material>
    	</visual>
    	<collision>
      		<origin rpy="0 0 0" xyz="-0.02 0 -0.29"/>
			<geometry>
      		  	<cylinder length="0.62" radius="0.18"/>
      		</geometry>
    	</collision>
    	<inertial>
      		<origin rpy="0 0 0" xyz="0 0 -0.5"/>
      		<mass value="60.86397744"/>
      		<inertia ixx="5.0635929" ixy="0.00103417" ixz="0.80199628" iyy="6.08689388" iyz="0.00105311" izz="4.96191932"/>
		</inertial>
  	</link>

	<joint name="doosan_pedestal_fixed" type="fixed">
		<origin rpy="0 0 0" xyz="0.0 0.0 0.0"/>
		<parent link="base_0"/>
		<child link="doosan_pedestal"/>
	</joint>  

	<link name="doosan_controller_box">
		<collision>
		<origin rpy="0 0 0" xyz="-0.325 0 -0.38"/>
		<geometry>
			<box size="0.22 0.4 0.53"/>
		</geometry>
		</collision>
	</link>

	<joint name="doosan_controller_box_fixed" type="fixed">
		<origin rpy="0 0 0" xyz="0.0 0.0 0.0"/>
		<parent link="base_0"/>
		<child link="doosan_controller_box"/>
	</joint>

	<link name="doosan_pedestal_feet">
		<collision>
		<origin rpy="0 0 0" xyz="-0.1225 0 -0.758"/>
		<geometry>
			<box size="0.77 0.7 0.31"/>
		</geometry>
		</collision>
	</link>

	<joint name="doosan_pedestal_feet_fixed" type="fixed">
		<origin rpy="0 0 0" xyz="0.0 0.0 0.0"/>
		<parent link="base_0"/>
		<child link="doosan_pedestal_feet"/>
	</joint>

    <!-- joint 1 -->
    <joint name="joint1" type="revolute">
        <parent link="base_0" />
        <child link="link1" />
        <origin rpy="0 0 0" xyz="0 0 0.195" />
        <axis xyz="0 0 1" />
        <limit effort="411" lower="-6.2832" upper="6.2832" velocity="3.1416"/>
        <dynamics friction="0" />
    </joint>
    <link name="link1">
        <inertial>
            <mass value="7.863"/>
            <origin xyz="4.4e-05    0.029982    -0.01112"/>
            <inertia ixx="0.045839" ixy="1.2759e-05" ixz="-3.6168e-05" iyy="0.032913"
                iyz="-0.0029965"
                izz="0.044399"/>
        </inertial>
        <collision>
            <geometry>
                <cylinder radius="0.08" length="0.2"/>
            </geometry>
        </collision>
        <visual>
            <origin rpy="0 0 0" xyz="0 0 0" />
            <geometry>
                <mesh filename="meshes/a0912_blue/A0912_1_0.stl" scale="0.001 0.001 0.001" />
            </geometry>
			<material name="dr_navy">
				<color rgba="0.15686 0.19215 0.25490 1" />
			</material>
        </visual>
        <visual>
            <origin rpy="0 0 0" xyz="0 0 0" />
            <geometry>
                <mesh filename="meshes/a0912_blue/A0912_1_1.stl" scale="0.001 0.001 0.001" />
            </geometry>
			<material name="dr_navy">
				<color rgba="0.15686 0.19215 0.25490 1" />
			</material>
        </visual>
        <visual>
            <origin rpy="0 0 0" xyz="0 0 0" />
            <geometry>
                <mesh filename="meshes/a0912_blue/A0912_1_2.stl" scale="0.001 0.001 0.001" />
            </geometry>
			<material name="dr_navy">
				<color rgba="0.15686 0.19215 0.25490 1" />
			</material>
        </visual>
    </link>
    <!-- joint2 -->
    <joint name="joint2" type="revolute">
        <parent link="link1" />
        <child link="link2" />
        <origin rpy="0 -1.571 -1.571" xyz="0 0.039 0" />
        <axis xyz="0 0 1" />
        <limit effort="411" lower="-6.2832" upper="6.2832" velocity="3.1416"/>
        <dynamics friction="0" />
    </joint>
    <link name="link2">
        <inertial>
            <mass value="10.985"/>
            <origin xyz="0.19748    0.001426     0.13191"/>
            <inertia ixx="0.04446" ixy="-0.0049948" ixz="-0.010992" iyy="0.67642" iyz="-2.8483e-05"
                izz="0.67428"/>
        </inertial>
        <collision>
            <origin rpy="0 -1.571 0" xyz="0.3 0 0.1525" />
            <geometry>
                <cylinder radius="0.08" length="0.6"/>
            </geometry>
        </collision>
        <visual>
            <origin rpy="0 0 0" xyz="0 0 0" />
            <geometry>
                <mesh filename="meshes/a0912_blue/A0912_2_0.stl" scale="0.001 0.001 0.001" />
            </geometry>
			<material name="dr_navy">
				<color rgba="0.15686 0.19215 0.25490 1" />
			</material>
        </visual>
        <visual>
            <origin rpy="0 0 0" xyz="0 0 0" />
            <geometry>
                <mesh filename="meshes/a0912_blue/A0912_2_1.stl" scale="0.001 0.001 0.001" />
            </geometry>
			<material name="dr_gray">
				<color rgba="0.490 0.490 0.486 1.0"/>
			</material>
        </visual>
        <visual>
            <origin rpy="0 0 0" xyz="0 0 0" />
            <geometry>
                <mesh filename="meshes/a0912_blue/A0912_2_2.stl" scale="0.001 0.001 0.001" />
            </geometry>
			<material name="dr_navy">
				<color rgba="0.15686 0.19215 0.25490 1" />
			</material>
        </visual>
    </link>
    <!-- joint3 -->
    <joint name="joint3" type="revolute">
        <parent link="link2" />
        <child link="link3" />
        <origin rpy="0 0 1.571" xyz="0.56 0 0" />
        <axis xyz="0 0 1" />
        <limit effort="194" lower="-2.7925" upper="2.7925" velocity="3.1416"/>
        <dynamics friction="0" />
    </joint>
    <link name="link3">
        <inertial>
            <mass value="2.881"/>
            <origin xyz="8.5e-05   -0.002513    0.032058"/>
            <inertia ixx="0.012756" ixy="-5.4257e-06" ixz="1.6402e-05" iyy="0.011416"
                iyz="-0.0001989"
                izz="0.0080652"/>
        </inertial>
        <visual>
            <origin rpy="0 0 0" xyz="0 0 0" />
            <geometry>
                <mesh filename="meshes/a0912_blue/A0912_3_0.stl" scale="0.001 0.001 0.001" />
            </geometry>
			<material name="dr_navy">
				<color rgba="0.15686 0.19215 0.25490 1" />
			</material>
        </visual>
        <visual>
            <origin rpy="0 0 0" xyz="0 0 0" />
            <geometry>
                <mesh filename="meshes/a0912_blue/A0912_3_1.stl" scale="0.001 0.001 0.001" />
            </geometry>
			<material name="dr_navy">
				<color rgba="0.15686 0.19215 0.25490 1" />
			</material>
        </visual>
    </link>
    <!-- joint4 -->
    <joint name="joint4" type="revolute">
        <parent link="link3" />
        <child link="link4" />
        <origin rpy="1.571 0 0" xyz="0 -0.516 0" />
        <axis xyz="0 0 1" />
        <limit effort="50" lower="-6.2832" upper="6.2832" velocity="6.2832"/>
        <dynamics friction="0" />
    </joint>
    <link name="link4">
        <inertial>
            <mass value="3.273"/>
            <origin xyz="-9.6e-05    0.085314    -0.13975"/>
            <inertia ixx="0.12246" ixy="2.3905e-05" ixz="2.5022e-05" iyy="0.11307" iyz="-0.027995"
                izz="0.017186"/>
        </inertial>
        <collision>
            <origin rpy="-0.46 0 0" xyz="0 0.075 -0.2" />
            <geometry>
                <cylinder radius="0.05" length="0.4"/>
            </geometry>
        </collision>
        <visual>
            <origin rpy="0 0 0" xyz="0 0 0" />
            <geometry>
                <mesh filename="meshes/a0912_blue/A0912_4_0.stl" scale="0.001 0.001 0.001" />
            </geometry>
			<material name="dr_navy">
				<color rgba="0.15686 0.19215 0.25490 1" />
			</material>
        </visual>
        <visual>
            <origin rpy="0 0 0" xyz="0 0 0" />
            <geometry>
                <mesh filename="meshes/a0912_blue/A0912_4_1.stl" scale="0.001 0.001 0.001" />
            </geometry>
			<material name="dr_navy">
				<color rgba="0.15686 0.19215 0.25490 1" />
			</material>
        </visual>
    </link>
    <!-- joint5 -->
    <joint name="joint5" type="revolute">
        <parent link="link4" />
        <child link="link5" />
        <origin rpy="-1.571 0 0" xyz="0 0 0" />
        <axis xyz="0 0 1" />
        <limit effort="50" lower="-6.2832" upper="6.2832" velocity="6.2832"/>
        <dynamics friction="0" />
    </joint>
    <link name="link5">
        <inertial>
            <mass value="2.141"/>
            <origin xyz="0.000109   -0.003286     0.01477"/>
            <inertia ixx="0.013145" ixy="-4.7132e-06" ixz="8.5804e-06" iyy="0.0073072"
                iyz="-5.999e-05"
                izz="0.0090476"/>
        </inertial>
        <collision>
            <origin rpy="1.571 0 0" xyz="0 0 0" />
            <geometry>
                <cylinder radius="0.06" length="0.15"/>
            </geometry>
        </collision>
        <visual>
            <origin rpy="0 0 0" xyz="0 0 0" />
            <geometry>
                <mesh filename="meshes/a0912_blue/A0912_5_0.stl" scale="0.001 0.001 0.001" />
            </geometry>
			<material name="dr_navy">
				<color rgba="0.15686 0.19215 0.25490 1" />
			</material>
        </visual>
        <visual>
            <origin rpy="0 0 0" xyz="0 0 0" />
            <geometry>
                <mesh filename="meshes/a0912_blue/A0912_5_1.stl" scale="0.001 0.001 0.001" />
            </geometry>
			<material name="dr_navy">
				<color rgba="0.15686 0.19215 0.25490 1" />
			</material>
        </visual>
    </link>
    <!-- joint6 -->
    <joint name="joint6" type="revolute">
        <parent link="link5" />
        <child link="link6" />
        <origin rpy="1.571 0 0" xyz="0 -0.124 0" />
        <axis xyz="0 0 1" />
        <limit effort="50" lower="-6.2832" upper="6.2832" velocity="6.2832"/>
        <dynamics friction="0" />
    </joint>
    <link name="link6">
        <inertial>
            <mass value="0.784"/>
            <origin xyz="-1.9e-05      -6e-06    -0.05227"/>
            <inertia ixx="0.0067403" ixy="5.2373e-06" ixz="2.4957e-06" iyy="0.0048015"
                iyz="8.3671e-06"
                izz="0.0059696"/>
        </inertial>
        <visual>
            <origin rpy="0 0 0" xyz="0 0 0" />
            <geometry>
                <mesh filename="meshes/a0912_blue/A0912_6_0.stl" scale="0.001 0.001 0.001" />
            </geometry>
			<material name="dr_gray">
				<color rgba="0.490 0.490 0.486 1.0"/>
			</material>
        </visual>
    </link>
</robot>