<?xml version="1.0"?>
<robot name="iiwa7" xmlns:xacro="http://www.ros.org/wiki/xacro">
  <link name="iiwa7_link_0">
    <inertial>
      <origin xyz="-0.1 0 0.07" rpy="0 0 0"/>
      <mass value="5"/>
      <inertia ixx="0.05"  ixy="0"  ixz="0" iyy="0.06" iyz="0" izz="0.03" />
    </inertial>
    <visual>
      <origin xyz="0 0 0" rpy="0 0 0"/>
      <geometry>
        <mesh filename="meshes/visual/link_0.stl"/>
      </geometry>
      <material name="Grey">
        <color rgba="0.4 0.4 0.4 1.0"/>
      </material>
    </visual>
    <collision>
      <origin xyz="0 0 0" rpy="0 0 0"/>
      <geometry>
        <mesh filename="meshes/collision/link_0.stl"/>
      </geometry>
      <material name="Grey">
        <color rgba="0.4 0.4 0.4 1.0"/>
      </material>
    </collision>
    <self_collision_checking>
      <origin xyz="0 0 0" rpy="0 0 0"/>
      <geometry>
        <capsule radius="0.15" length="0.25"/>
      </geometry>
    </self_collision_checking>
  </link>

  <link name="iiwa7_pedestal">
    <visual>
      <origin rpy="1.57079632679 0 -1.57079632679" xyz="0.26 0.345 -0.91488"/>
      <geometry>
        <mesh filename="meshes/iiwa7_pedestal/pedestal.STL"/>
      </geometry>
      <material name="darkgray">
        <color rgba=".2 .2 .2 1"/>
      </material>
    </visual>
    <collision>
      <origin rpy="0 0 0" xyz="-0.02 0 -0.29"/>
      <geometry>
        <cylinder length="0.62" radius="0.18"/>
      </geometry>
    </collision>
    <inertial>
      <origin rpy="0 0 0" xyz="0 0 -0.5"/>
      <mass value="60.86397744"/>
      <inertia ixx="5.0635929" ixy="0.00103417" ixz="0.80199628" iyy="6.08689388" iyz="0.00105311" izz="4.96191932"/>
    </inertial>
  </link>

  <joint name="iiwa7_pedestal_fixed" type="fixed">
    <origin rpy="0 0 0" xyz="0.0 0.0 0.0"/>
    <parent link="iiwa7_link_0"/>
    <child link="iiwa7_pedestal"/>
  </joint>  

  <link name="iiwa7_controller_box">
    <collision>
      <origin rpy="0 0 0" xyz="-0.325 0 -0.38"/>
      <geometry>
        <box size="0.22 0.4 0.53"/>
      </geometry>
    </collision>
  </link>

  <joint name="iiwa7_controller_box_fixed" type="fixed">
    <origin rpy="0 0 0" xyz="0.0 0.0 0.0"/>
    <parent link="iiwa7_link_0"/>
    <child link="iiwa7_controller_box"/>
  </joint>

  <link name="iiwa7_pedestal_feet">
    <collision>
      <origin rpy="0 0 0" xyz="-0.1225 0 -0.758"/>
      <geometry>
        <box size="0.77 0.7 0.31"/>
      </geometry>
    </collision>
  </link>

  <joint name="iiwa7_pedestal_feet_fixed" type="fixed">
    <origin rpy="0 0 0" xyz="0.0 0.0 0.0"/>
    <parent link="iiwa7_link_0"/>
    <child link="iiwa7_pedestal_feet"/>
  </joint>


  <!-- joint between link_0 and link_1 -->
  <joint name="iiwa7_joint_1" type="revolute">
    <parent link="iiwa7_link_0"/>
    <child link="iiwa7_link_1"/>
    <origin xyz="0 0 0.15" rpy="0 0 0"/>
    <axis xyz="0 0 1"/>
    <limit lower="-2.96706" upper="2.96706"
            effort="${max_effort}" velocity="${max_velocity}" />
    <safety_controller soft_lower_limit="${-168 * PI / 180}"
                        soft_upper_limit="${168 * PI / 180}"
                        k_position="${safety_controller_k_pos}"
                        k_velocity="${safety_controller_k_vel}"/> 
    <dynamics damping="${joint_damping}"/>
  </joint>
    
  <link name="iiwa7_link_1">
    <inertial>
      <origin xyz="0 -0.03 0.12" rpy="0 0 0"/>
      <mass value="3.4525"/>
      <inertia ixx="0.02183"  ixy="0"  ixz="0" iyy="0.007703" iyz="-0.003887" izz="0.02083" />
    </inertial>
    <visual>
      <origin xyz="0 0 0.0075" rpy="0 0 0"/>
      <geometry>
        <mesh filename="meshes/visual/link_1.stl"/>
      </geometry>
      <material name="Orange">
        <color rgba="1.0 0.423529411765 0.0392156862745 1.0"/>
      </material>
    </visual>
    <collision>
      <origin xyz="0 0 0.0075" rpy="0 0 0"/>
      <geometry>
        <mesh filename="meshes/collision/link_1.stl"/>
      </geometry>
      <material name="Orange">
        <color rgba="1.0 0.423529411765 0.0392156862745 1.0"/>
      </material>
    </collision>
  </link>
    
  <joint name="iiwa7_joint_2" type="revolute">
    <parent link="iiwa7_link_1"/>
    <child link="iiwa7_link_2"/>
    <origin xyz="0 0 0.19" rpy="1.570796325 0 3.1415926"/>
    <axis xyz="0 0 1"/>
    <limit lower="-2.0944" upper="2.0944"
            effort="${max_effort}" velocity="${max_velocity}" />
    <safety_controller soft_lower_limit="${-118 * PI / 180}"
                        soft_upper_limit="${118 * PI / 180}"
                        k_position="${safety_controller_k_pos}"
                        k_velocity="${safety_controller_k_vel}"/> 
    <dynamics damping="${joint_damping}"/>
  </joint>
    
  <link name="iiwa7_link_2">
    <inertial>
      <origin xyz="0.0003 0.059 0.042" rpy="0 0 0"/>
      <mass value="3.4821"/>
      <inertia ixx="0.02076"  ixy="0"  ixz="-0.003626" iyy="0.02179" iyz="0" izz="0.00779" />
    </inertial>
    <visual>
      <origin xyz="0 0 0" rpy="0 0 0"/>
      <geometry>
        <mesh filename="meshes/visual/link_2.stl"/>
      </geometry>
      <material name="Orange">
        <color rgba="1.0 0.423529411765 0.0392156862745 1.0"/>
      </material>
    </visual>
    
    <collision>
      <origin xyz="0 0 0" rpy="0 0 0"/>
      <geometry>
        <mesh filename="meshes/collision/link_2.stl"/>
      </geometry>
      <material name="Orange">
        <color rgba="1.0 0.423529411765 0.0392156862745 1.0"/>
      </material>
    </collision>
  </link>
    
  <joint name="iiwa7_joint_3" type="revolute">
    <parent link="iiwa7_link_2"/>
    <child link="iiwa7_link_3"/>
    <origin xyz="0 0.21 0" rpy="1.570796325 0 3.1415926"/>
    <axis xyz="0 0 1"/>
    <limit lower="-2.96706" upper="2.96706"
            effort="${max_effort}" velocity="${max_velocity}" />
    <safety_controller soft_lower_limit="${-168 * PI / 180}"
                        soft_upper_limit="${168 * PI / 180}"
                        k_position="${safety_controller_k_pos}"
                        k_velocity="${safety_controller_k_vel}"/> 
    <dynamics damping="${joint_damping}"/>
  </joint>
    
  <link name="iiwa7_link_3">
    <inertial>
      <origin xyz="0 0.03 0.13" rpy="0 0 0"/>
      <mass value="4.05623"/>
      <inertia ixx="0.03204"  ixy="0"  ixz="0" iyy="0.00972" iyz="0.006227" izz="0.03042" />
    </inertial>
    
    <visual>
      <origin xyz="0 0 -0.026" rpy="0 0 0"/>
      <geometry>
        <mesh filename="meshes/visual/link_3.stl"/>
      </geometry>
      <material name="Orange">
        <color rgba="1.0 0.423529411765 0.0392156862745 1.0"/>
      </material>
    </visual>
    
    <collision>
      <origin xyz="0 0 -0.026" rpy="0 0 0"/>
      <geometry>
        <mesh filename="meshes/collision/link_3.stl"/>
      </geometry>
      <material name="Orange">
        <color rgba="1.0 0.423529411765 0.0392156862745 1.0"/>
      </material>
    </collision>
    
  </link>
    
  <joint name="iiwa7_joint_4" type="revolute">
    <parent link="iiwa7_link_3"/>
    <child link="iiwa7_link_4"/>
    <origin xyz="0 0 0.19" rpy="1.570796325 0 0"/>
    <axis xyz="0 0 1"/>
    <limit lower="-2.0944" upper="2.0944"
            effort="${max_effort}" velocity="${max_velocity}" />
    <safety_controller soft_lower_limit="${-118 * PI / 180}"
                        soft_upper_limit="${118 * PI / 180}"
                        k_position="${safety_controller_k_pos}"
                        k_velocity="${safety_controller_k_vel}"/> 
    <dynamics damping="${joint_damping}"/>
  </joint>
    
  <link name="iiwa7_link_4">
    <inertial>
      <origin xyz="0 0.067 0.034" rpy="0 0 0"/>
      <mass value="3.4822"/>
      <inertia ixx="0.02178"  ixy="0"  ixz="0" iyy="0.02075" iyz="-0.003625" izz="0.007785" />
    </inertial>
    
    <visual>
      <origin xyz="0 0 0" rpy="0 0 0"/>
      <geometry>
        <mesh filename="meshes/visual/link_4.stl"/>
      </geometry>
      <material name="Orange">
        <color rgba="1.0 0.423529411765 0.0392156862745 1.0"/>
      </material>
    </visual>
    
    <collision>
      <origin xyz="0 0 0" rpy="0 0 0"/>
      <geometry>
        <mesh filename="meshes/collision/link_4.stl"/>
      </geometry>
      <material name="Orange">
        <color rgba="1.0 0.423529411765 0.0392156862745 1.0"/>
      </material>
    </collision>
  </link>
    
  <joint name="iiwa7_joint_5" type="revolute">
    <parent link="iiwa7_link_4"/>
    <child link="iiwa7_link_5"/>
    <origin xyz="0 0.21 0" rpy="-1.570796325 3.1415926 0"/>
    <axis xyz="0 0 1"/>
    <limit lower="-2.96706" upper="2.96706"
            effort="${max_effort}" velocity="${max_velocity}" />
    <safety_controller soft_lower_limit="${-168 * PI / 180}"
                        soft_upper_limit="${168 * PI / 180}"
                        k_position="${safety_controller_k_pos}"
                        k_velocity="${safety_controller_k_vel}"/> 
    <dynamics damping="${joint_damping}"/>
  </joint>
    
  <link name="iiwa7_link_5">
    <inertial>
      <origin xyz="0.0001 0.021 0.076" rpy="0 0 0"/>
      <mass value="2.1633"/>
      <inertia ixx="0.01287"  ixy="0"  ixz="0" iyy="0.005708" iyz="-0.003946" izz="0.01112" />
    </inertial>
    
    <visual>
      <origin xyz="0 0 -0.026" rpy="0 0 0"/>
      <geometry>
        <mesh filename="meshes/visual/link_5.stl"/>
      </geometry>
      <material name="Orange">
        <color rgba="1.0 0.423529411765 0.0392156862745 1.0"/>
      </material>
    </visual>
    
    <collision>
      <origin xyz="0 0 -0.026" rpy="0 0 0"/>
      <geometry>
        <mesh filename="meshes/collision/link_5.stl"/>
      </geometry>
      <material name="Orange">
        <color rgba="1.0 0.423529411765 0.0392156862745 1.0"/>
      </material>
    </collision>
  </link>
    
  <joint name="iiwa7_joint_6" type="revolute">
    <parent link="iiwa7_link_5"/>
    <child link="iiwa7_link_6"/>
    <origin xyz="0 0.06070 0.19" rpy="1.570796325 0 0"/>
    <axis xyz="0 0 1"/>
    <limit lower="-2.0944" upper="2.0944"
            effort="${max_effort}" velocity="${max_velocity}" />
    <safety_controller soft_lower_limit="${-118 * PI / 180}"
                        soft_upper_limit="${118 * PI / 180}"
                        k_position="${safety_controller_k_pos}"
                        k_velocity="${safety_controller_k_vel}"/> 
    <dynamics damping="${joint_damping}"/>
  </joint>
    
  <link name="iiwa7_link_6">
    <inertial>
      <origin xyz="0 0.0006 0.0004" rpy="0 0 0"/>
      <mass value="2.3466"/>
      <inertia ixx="0.006509"  ixy="0"  ixz="0" iyy="0.006259" iyz="0.00031891" izz="0.004527" />
    </inertial>
    
    <visual>
      <origin xyz="0 0 0" rpy="0 0 0"/>
      <geometry>
        <mesh filename="meshes/visual/link_6.stl"/>
      </geometry>
      <material name="Orange">
        <color rgba="1.0 0.423529411765 0.0392156862745 1.0"/>
      </material>
    </visual>
    
    <collision>
      <origin xyz="0 0 0" rpy="0 0 0"/>
      <geometry>
        <mesh filename="meshes/collision/link_6.stl"/>
      </geometry>
      <material name="Orange">
        <color rgba="1.0 0.423529411765 0.0392156862745 1.0"/>
      </material>
    </collision>
  </link>
    
  <joint name="iiwa7_joint_7" type="revolute">
    <parent link="iiwa7_link_6"/>
    <child link="iiwa7_link_7"/>
    <origin xyz="0 0.081 0.06070" rpy="-1.570796325 3.1415926 0"/>
    <axis xyz="0 0 1"/>
    <limit lower="-3.05433" upper="3.05433"
            effort="${max_effort}" velocity="${max_velocity}" />
    <safety_controller soft_lower_limit="${-173 * PI / 180}"
                        soft_upper_limit="${173 * PI / 180}"
                        k_position="${safety_controller_k_pos}"
                        k_velocity="${safety_controller_k_vel}"/> 
    <dynamics damping="${joint_damping}"/>
  </joint>
    
  <link name="iiwa7_link_7">
    <inertial>
      <origin xyz="0 0 0.02" rpy="0 0 0"/>
      <mass value="3.129"/>
      <inertia ixx="0.01464"  ixy="0.0005912"  ixz="0" iyy="0.01465" iyz="0" izz="0.002872" />
    </inertial>
    
    <visual>
      <origin xyz="0 0 -0.0005" rpy="0 0 0"/>
      <geometry>
        <mesh filename="meshes/visual/link_7.stl"/>
      </geometry>
      <material name="Grey">
        <color rgba="0.4 0.4 0.4 1.0"/>
      </material>
    </visual>
    
    <collision>
      <origin xyz="0 0 -0.0005" rpy="0 0 0"/>
      <geometry>
        <mesh filename="meshes/collision/link_7.stl"/>
      </geometry>
      <material name="Grey">
        <color rgba="0.4 0.4 0.4 1.0"/>
      </material>
    </collision>
  </link>
    
  <joint name="iiwa7_right_hand_fixed" type="fixed">
    <parent link="iiwa7_link_7"/>
    <child link="iiwa7_right_hand"/>
    <origin xyz="0 0 0.044" rpy="0 0 0"/>
  </joint>
    
  <link name="iiwa7_right_hand">
    <inertial>
      <origin rpy="0 0 0" xyz="0 0 0"/>
      <mass value="0"/>
      <inertia ixx="0.0" ixy="0.0" ixz="0.0" iyy="0.0" iyz="0.0" izz="0.0"/>
    </inertial>
  </link>

    <link name="right_gripper">
        <inertial>
            <origin xyz="8.625E-08 -4.6583E-06 0.03145" rpy="0 0 0" />
            <mass value="0.22652" />
            <inertia ixx="0.00020005" ixy="-4.2442E-10" ixz="-2.9069E-10" iyy="0.00017832" iyz="-3.4402E-08" izz="0.00013478" />
        </inertial>
        <visual>
        <origin xyz="0 0 -0.061525" quat="0 0.707388 -0.706825 0" />
        <geometry>
            <mesh filename="meshes/visual/robotiq_arg2f_base_link.stl" />
        </geometry>
        <material name="">
            <color rgba="0.1 0.1 0.1 1" />
        </material>
        </visual>
        <collision>
        <origin xyz="0 0 -0.061525" rpy="0 0 0" />
        <geometry>
            <mesh filename="meshes/collision/robotiq_arg2f_base_link.stl" />
        </geometry>
        </collision>
    </link>

    <joint name="iiwa7_right_gripper_fixed" type="fixed">
        <origin quat="0 -0.707105 0.707108 0 " xyz="0 0 -0.0625"/>
        <parent link="iiwa7_right_hand"/>
        <child link="right_gripper"/>
        <axis xyz="0 0 0"/>
    </joint>

    <joint name="finger_joint" type="fixed">
        <origin xyz="0.030601 2.43684e-05 -0.11643" quat="-0.64507 0.290316 -0.290085 0.644556"/>
        <parent link="right_gripper" />
        <child link="left_outer_knuckle" />
        <axis xyz="-1 0 0" />
        <limit lower="0" upper="0.7" velocity="2.0" effort="1000" />
    </joint>

    <joint name="right_outer_knuckle_joint" type="fixed">
        <origin xyz="-0.030601 -2.43684e-05 -0.11643" quat="0.644556 -0.290085 -0.290316 0.64507"/>
        <parent link="right_gripper" />
        <child link="right_outer_knuckle" />
        <axis xyz="1 0 0" />
        <limit lower="-0.725" upper="0.725" velocity="2.0" effort="1000" />
        <mimic joint="finger_joint" multiplier="-1" offset="0" />
    </joint>

    <link name="right_outer_knuckle">
        <inertial>
            <origin xyz="-0.000200000000003065 0.0199435877845359 0.0292245259211331" rpy="0 0 0" />
            <mass value="0.00853198276973456" />
            <inertia
                ixx="2.89328108496468E-06"
                ixy="-1.57935047237397E-19"
                ixz="-1.93980378593255E-19"
                iyy="1.86719750325683E-06"
                iyz="-1.21858577871576E-06"
                izz="1.21905238907251E-06" />
        </inertial>
        <visual>
            <origin xyz="0 0 0" rpy="0 0 0" />
            <geometry>
                <mesh filename="meshes/visual/robotiq_arg2f_140_outer_knuckle.stl" />
            </geometry>
            <material name="">
                <color rgba="0.792156862745098 0.819607843137255 0.933333333333333 1" />
            </material>
        </visual>
        <collision>
            <origin xyz="0 0 0" rpy="0 0 0" />
            <geometry>
                <mesh filename="meshes/collision/robotiq_arg2f_140_outer_knuckle.stl" />
            </geometry>
        </collision>
    </link>

    <link name="right_outer_finger">
        <inertial>
            <origin xyz="0.00030115855001899 0.0373907951953854 -0.0208027427000385" rpy="0 0 0" />
            <mass value="0.022614240507152" />
            <inertia
                ixx="1.52518312458174E-05"
                ixy="9.76583423954399E-10"
                ixz="-5.43838577022588E-10"
                iyy="6.17694243867776E-06"
                iyz="6.78636130740228E-06"
                izz="1.16494917907219E-05" />
        </inertial>
        <visual>
            <origin xyz="0 0 0" rpy="0 0 0" />
            <geometry>
                <mesh filename="meshes/visual/robotiq_arg2f_140_outer_finger.stl" />
            </geometry>
            <material name="">
                <color rgba="0.1 0.1 0.1 1" />
            </material>
        </visual>
        <collision>
            <origin xyz="0 0 0" rpy="0 0 0" />
            <geometry>
            <mesh filename="meshes/collision/robotiq_arg2f_140_outer_finger.stl" />
            </geometry>
        </collision>
    </link>

    <link name="right_inner_knuckle">
        <inertial>
            <origin xyz="0.000123011831763771 0.0507850843201817 0.00103968640075166" rpy="0 0 0" />
            <mass value="0.0271177346495152" />
            <inertia
                ixx="2.61910379223783E-05"
                ixy="-2.43616858946494E-07"
                ixz="-6.37789906117123E-09"
                iyy="2.8270243746167E-06"
                iyz="-5.37200748039765E-07"
                izz="2.83695868220296E-05" />
        </inertial>
        <visual>
            <origin xyz="0 0 0" rpy="0 0 0" />
            <geometry>
            <mesh filename="meshes/visual/robotiq_arg2f_140_inner_knuckle.stl" />
            </geometry>
            <material name="">
            <color rgba="0.1 0.1 0.1 1" />
            </material>
        </visual>
        <collision>
            <origin xyz="0 0 0" rpy="0 0 0" />
            <geometry>
            <mesh filename="meshes/collision/robotiq_arg2f_140_inner_knuckle.stl" />
            </geometry>
        </collision>
    </link>

    <link name="right_inner_finger">
        <inertial>
            <origin xyz="0.000299999999999317 0.0160078233491243 -0.0136945669206257" rpy="0 0 0" />
            <mass value="0.0104003125914103" />
            <inertia
                ixx="2.71909453810972E-06"
                ixy="1.35402465472579E-21"
                ixz="-7.1817349065269E-22"
                iyy="7.69100314106116E-07"
                iyz="6.74715432769696E-07"
                izz="2.30315190420171E-06" />
        </inertial>
        <visual>
            <origin xyz="0 0 0" rpy="0 0 0" />
            <geometry>
            <mesh filename="meshes/visual/robotiq_arg2f_140_inner_finger.stl" />
            </geometry>
            <material name="">
            <color rgba="0.1 0.1 0.1 1" />
            </material>
        </visual>
        <collision>
            <origin xyz="0 0 0" rpy="0 0 0" />
            <geometry>
            <mesh filename="meshes/collision/robotiq_arg2f_140_inner_finger.stl" />
            </geometry>
        </collision>
    </link>

    <link name="right_inner_finger_pad">
        <visual>
            <origin xyz="0 0 0" rpy="0 0 0" />
            <geometry>
            <box size="0.027 0.065 0.0075"/>
            </geometry>
            <material name="">
            <color rgba="0.9 0.9 0.9 1" />
            </material>
        </visual>
        <collision>
            <origin xyz="0 0 0" rpy="0 0 0" />
            <geometry>
            <box size="0.03 0.07 0.0075"/>
            </geometry>
            <material name="">
            <color rgba="0.9 0.0 0.0 1" />
            </material>
        </collision>
    </link>

    <joint name="right_outer_finger_joint" type="fixed">
        <origin xyz="0 0.01821998610742 0.0260018192872234" rpy="0 0 0" />
        <parent link="right_outer_knuckle" />
        <child link="right_outer_finger" />
        <axis xyz="1 0 0" />
    </joint>

    <joint name="right_inner_knuckle_joint" type="fixed">
        <origin xyz="-0.0127 -1.01133e-05 -0.122945" quat="-0.644556 0.290085 0.290316 -0.64507" />
        <parent link="right_gripper" />
        <child link="right_inner_knuckle" />
        <axis xyz="1 0 0" />
        <limit lower="-0.8757" upper="0.8757" velocity="2.0" effort="1000" />
        <mimic joint="finger_joint" multiplier="-1" offset="0" />
    </joint>

    <joint name="right_inner_finger_joint" type="fixed">
        <origin xyz="0 0.0999754 -0.00221853" quat="0.935013 -0.354613 0 0" />
        <parent link="right_outer_finger" />
        <child link="right_inner_finger" />
        <axis xyz="1 0 0" />
        <limit lower="-0.8757" upper="0.8757" velocity="2.0" effort="1000" />
        <mimic joint="finger_joint" multiplier="1" offset="0" />
    </joint>

    <joint name="right_inner_finger_pad_joint" type="fixed">
        <origin xyz="0 0.0457554 -0.0272203" rpy="0 0 0" />
        <parent link="right_inner_finger" />
        <child link="right_inner_finger_pad" />
        <axis xyz="0 0 1" />
    </joint>

    <link name="left_outer_knuckle">
        <inertial>
            <origin xyz="-0.000200000000003065 0.0199435877845359 0.0292245259211331" rpy="0 0 0" />
            <mass value="0.00853198276973456" />
            <inertia
                ixx="2.89328108496468E-06"
                ixy="-1.57935047237397E-19"
                ixz="-1.93980378593255E-19"
                iyy="1.86719750325683E-06"
                iyz="-1.21858577871576E-06"
                izz="1.21905238907251E-06" />
        </inertial>
        <visual>
            <origin xyz="0 0 0" rpy="0 0 0" />
            <geometry>
                <mesh filename="meshes/visual/robotiq_arg2f_140_outer_knuckle.stl" />
            </geometry>
            <material name="">
                <color rgba="0.792156862745098 0.819607843137255 0.933333333333333 1" />
            </material>
        </visual>
        <collision>
            <origin xyz="0 0 0" rpy="0 0 0" />
            <geometry>
                <mesh filename="meshes/collision/robotiq_arg2f_140_outer_knuckle.stl" />
            </geometry>
        </collision>
    </link>

    <link name="left_outer_finger">
        <inertial>
            <origin xyz="0.00030115855001899 0.0373907951953854 -0.0208027427000385" rpy="0 0 0" />
            <mass value="0.022614240507152" />
            <inertia
                ixx="1.52518312458174E-05"
                ixy="9.76583423954399E-10"
                ixz="-5.43838577022588E-10"
                iyy="6.17694243867776E-06"
                iyz="6.78636130740228E-06"
                izz="1.16494917907219E-05" />
        </inertial>
        <visual>
            <origin xyz="0 0 0" rpy="0 0 0" />
            <geometry>
                <mesh filename="meshes/visual/robotiq_arg2f_140_outer_finger.stl" />
            </geometry>
            <material name="">
                <color rgba="0.1 0.1 0.1 1" />
            </material>
        </visual>
        <collision>
            <origin xyz="0 0 0" rpy="0 0 0" />
            <geometry>
            <mesh filename="meshes/collision/robotiq_arg2f_140_outer_finger.stl" />
            </geometry>
        </collision>
    </link>

    <link name="left_inner_knuckle">
        <inertial>
            <origin xyz="0.000123011831763771 0.0507850843201817 0.00103968640075166" rpy="0 0 0" />
            <mass value="0.0271177346495152" />
            <inertia
                ixx="2.61910379223783E-05"
                ixy="-2.43616858946494E-07"
                ixz="-6.37789906117123E-09"
                iyy="2.8270243746167E-06"
                iyz="-5.37200748039765E-07"
                izz="2.83695868220296E-05" />
        </inertial>
        <visual>
            <origin xyz="0 0 0" rpy="0 0 0" />
            <geometry>
            <mesh filename="meshes/visual/robotiq_arg2f_140_inner_knuckle.stl" />
            </geometry>
            <material name="">
            <color rgba="0.1 0.1 0.1 1" />
            </material>
        </visual>
        <collision>
            <origin xyz="0 0 0" rpy="0 0 0" />
            <geometry>
            <mesh filename="meshes/collision/robotiq_arg2f_140_inner_knuckle.stl" />
            </geometry>
        </collision>
    </link>

    <link name="left_inner_finger">
        <inertial>
            <origin xyz="0.000299999999999317 0.0160078233491243 -0.0136945669206257" rpy="0 0 0" />
            <mass value="0.0104003125914103" />
            <inertia
                ixx="2.71909453810972E-06"
                ixy="1.35402465472579E-21"
                ixz="-7.1817349065269E-22"
                iyy="7.69100314106116E-07"
                iyz="6.74715432769696E-07"
                izz="2.30315190420171E-06" />
        </inertial>
        <visual>
            <origin xyz="0 0 0" rpy="0 0 0" />
            <geometry>
            <mesh filename="meshes/visual/robotiq_arg2f_140_inner_finger.stl" />
            </geometry>
            <material name="">
            <color rgba="0.1 0.1 0.1 1" />
            </material>
        </visual>
        <collision>
            <origin xyz="0 0 0" rpy="0 0 0" />
            <geometry>
            <mesh filename="meshes/collision/robotiq_arg2f_140_inner_finger.stl" />
            </geometry>
        </collision>
    </link>

    <link name="left_inner_finger_pad">
        <visual>
            <origin xyz="0 0 0" rpy="0 0 0" />
            <geometry>
            <box size="0.027 0.065 0.0075"/>
            </geometry>
            <material name="">
            <color rgba="0.9 0.9 0.9 1" />
            </material>
        </visual>
        <collision>
            <origin xyz="0 0 0" rpy="0 0 0" />
            <geometry>
            <box size="0.03 0.07 0.0075"/>
            </geometry>
            <material name="">
            <color rgba="0.9 0.0 0.0 1" />
            </material>
        </collision>
    </link>

    <joint name="left_outer_finger_joint" type="fixed">
        <origin xyz="0 0.01821998610742 0.0260018192872234" rpy="0 0 0" />
        <parent link="left_outer_knuckle" />
        <child link="left_outer_finger" />
        <axis xyz="1 0 0" />
    </joint>

    <joint name="left_inner_knuckle_joint" type="fixed">
        <origin xyz="0.0127 1.01133e-05 -0.122945" quat="-0.64507 0.290316 -0.290085 0.644556"/>
        <parent link="right_gripper" />
        <child link="left_inner_knuckle" />
        <axis xyz="1 0 0" />
        <limit lower="-0.8757" upper="0.8757" velocity="2.0" effort="1000" />
        <mimic joint="finger_joint" multiplier="-1" offset="0" />
    </joint>

    <joint name="left_inner_finger_joint" type="fixed">
        <origin xyz="0 0.0999754 -0.00221853" quat="0.935013 -0.354613 0 0"/>
        <parent link="left_outer_finger" />
        <child link="left_inner_finger" />
        <axis xyz="1 0 0" />
        <limit lower="-0.8757" upper="0.8757" velocity="2.0" effort="1000" />
        <mimic joint="finger_joint" multiplier="1" offset="0" />
    </joint>

    <joint name="left_inner_finger_pad_joint" type="fixed">
        <origin xyz="0 0.0457554 -0.0272203" rpy="0 0 0" />
        <parent link="left_inner_finger" />
        <child link="left_inner_finger_pad" />
        <axis xyz="0 0 1" />
    </joint>

</robot>
