<?xml version="1.0"?>
<robot name="iiwa7" xmlns:xacro="http://www.ros.org/wiki/xacro">
  <link name="iiwa7_link_0">
    <inertial>
      <origin xyz="-0.1 0 0.07" rpy="0 0 0"/>
      <mass value="5"/>
      <inertia ixx="0.05"  ixy="0"  ixz="0" iyy="0.06" iyz="0" izz="0.03" />
    </inertial>
    <visual>
      <origin xyz="0 0 0" rpy="0 0 0"/>
      <geometry>
        <mesh filename="meshes/visual/link_0.stl"/>
      </geometry>
      <material name="Grey">
        <color rgba="0.4 0.4 0.4 1.0"/>
      </material>
    </visual>
    <collision>
      <origin xyz="0 0 0" rpy="0 0 0"/>
      <geometry>
        <mesh filename="meshes/collision/link_0.stl"/>
      </geometry>
      <material name="Grey">
        <color rgba="0.4 0.4 0.4 1.0"/>
      </material>
    </collision>
    <self_collision_checking>
      <origin xyz="0 0 0" rpy="0 0 0"/>
      <geometry>
        <capsule radius="0.15" length="0.25"/>
      </geometry>
    </self_collision_checking>
  </link>

  <link name="iiwa7_pedestal">
    <visual>
      <origin rpy="1.57079632679 0 -1.57079632679" xyz="0.26 0.345 -0.91488"/>
      <geometry>
        <mesh filename="meshes/iiwa7_pedestal/pedestal.STL"/>
      </geometry>
      <material name="darkgray">
        <color rgba=".2 .2 .2 1"/>
      </material>
    </visual>
    <collision>
      <origin rpy="0 0 0" xyz="-0.02 0 -0.29"/>
      <geometry>
        <cylinder length="0.62" radius="0.18"/>
      </geometry>
    </collision>
    <inertial>
      <origin rpy="0 0 0" xyz="0 0 -0.5"/>
      <mass value="60.86397744"/>
      <inertia ixx="5.0635929" ixy="0.00103417" ixz="0.80199628" iyy="6.08689388" iyz="0.00105311" izz="4.96191932"/>
    </inertial>
  </link>

  <joint name="iiwa7_pedestal_fixed" type="fixed">
    <origin rpy="0 0 0" xyz="0.0 0.0 0.0"/>
    <parent link="iiwa7_link_0"/>
    <child link="iiwa7_pedestal"/>
  </joint>  

  <link name="iiwa7_controller_box">
    <collision>
      <origin rpy="0 0 0" xyz="-0.325 0 -0.38"/>
      <geometry>
        <box size="0.22 0.4 0.53"/>
      </geometry>
    </collision>
  </link>

  <joint name="iiwa7_controller_box_fixed" type="fixed">
    <origin rpy="0 0 0" xyz="0.0 0.0 0.0"/>
    <parent link="iiwa7_link_0"/>
    <child link="iiwa7_controller_box"/>
  </joint>

  <link name="iiwa7_pedestal_feet">
    <collision>
      <origin rpy="0 0 0" xyz="-0.1225 0 -0.758"/>
      <geometry>
        <box size="0.77 0.7 0.31"/>
      </geometry>
    </collision>
  </link>

  <joint name="iiwa7_pedestal_feet_fixed" type="fixed">
    <origin rpy="0 0 0" xyz="0.0 0.0 0.0"/>
    <parent link="iiwa7_link_0"/>
    <child link="iiwa7_pedestal_feet"/>
  </joint>


  <!-- joint between link_0 and link_1 -->
  <joint name="iiwa7_joint_1" type="revolute">
    <parent link="iiwa7_link_0"/>
    <child link="iiwa7_link_1"/>
    <origin xyz="0 0 0.15" rpy="0 0 0"/>
    <axis xyz="0 0 1"/>
    <limit lower="-2.96706" upper="2.96706"
            effort="${max_effort}" velocity="${max_velocity}" />
    <safety_controller soft_lower_limit="${-168 * PI / 180}"
                        soft_upper_limit="${168 * PI / 180}"
                        k_position="${safety_controller_k_pos}"
                        k_velocity="${safety_controller_k_vel}"/> 
    <dynamics damping="${joint_damping}"/>
  </joint>
    
  <link name="iiwa7_link_1">
    <inertial>
      <origin xyz="0 -0.03 0.12" rpy="0 0 0"/>
      <mass value="3.4525"/>
      <inertia ixx="0.02183"  ixy="0"  ixz="0" iyy="0.007703" iyz="-0.003887" izz="0.02083" />
    </inertial>
    <visual>
      <origin xyz="0 0 0.0075" rpy="0 0 0"/>
      <geometry>
        <mesh filename="meshes/visual/link_1.stl"/>
      </geometry>
      <material name="Orange">
        <color rgba="1.0 0.423529411765 0.0392156862745 1.0"/>
      </material>
    </visual>
    <collision>
      <origin xyz="0 0 0.0075" rpy="0 0 0"/>
      <geometry>
        <mesh filename="meshes/collision/link_1.stl"/>
      </geometry>
      <material name="Orange">
        <color rgba="1.0 0.423529411765 0.0392156862745 1.0"/>
      </material>
    </collision>
  </link>
    
  <joint name="iiwa7_joint_2" type="revolute">
    <parent link="iiwa7_link_1"/>
    <child link="iiwa7_link_2"/>
    <origin xyz="0 0 0.19" rpy="1.570796325 0 3.1415926"/>
    <axis xyz="0 0 1"/>
    <limit lower="-2.0944" upper="2.0944"
            effort="${max_effort}" velocity="${max_velocity}" />
    <safety_controller soft_lower_limit="${-118 * PI / 180}"
                        soft_upper_limit="${118 * PI / 180}"
                        k_position="${safety_controller_k_pos}"
                        k_velocity="${safety_controller_k_vel}"/> 
    <dynamics damping="${joint_damping}"/>
  </joint>
    
  <link name="iiwa7_link_2">
    <inertial>
      <origin xyz="0.0003 0.059 0.042" rpy="0 0 0"/>
      <mass value="3.4821"/>
      <inertia ixx="0.02076"  ixy="0"  ixz="-0.003626" iyy="0.02179" iyz="0" izz="0.00779" />
    </inertial>
    <visual>
      <origin xyz="0 0 0" rpy="0 0 0"/>
      <geometry>
        <mesh filename="meshes/visual/link_2.stl"/>
      </geometry>
      <material name="Orange">
        <color rgba="1.0 0.423529411765 0.0392156862745 1.0"/>
      </material>
    </visual>
    
    <collision>
      <origin xyz="0 0 0" rpy="0 0 0"/>
      <geometry>
        <mesh filename="meshes/collision/link_2.stl"/>
      </geometry>
      <material name="Orange">
        <color rgba="1.0 0.423529411765 0.0392156862745 1.0"/>
      </material>
    </collision>
  </link>
    
  <joint name="iiwa7_joint_3" type="revolute">
    <parent link="iiwa7_link_2"/>
    <child link="iiwa7_link_3"/>
    <origin xyz="0 0.21 0" rpy="1.570796325 0 3.1415926"/>
    <axis xyz="0 0 1"/>
    <limit lower="-2.96706" upper="2.96706"
            effort="${max_effort}" velocity="${max_velocity}" />
    <safety_controller soft_lower_limit="${-168 * PI / 180}"
                        soft_upper_limit="${168 * PI / 180}"
                        k_position="${safety_controller_k_pos}"
                        k_velocity="${safety_controller_k_vel}"/> 
    <dynamics damping="${joint_damping}"/>
  </joint>
    
  <link name="iiwa7_link_3">
    <inertial>
      <origin xyz="0 0.03 0.13" rpy="0 0 0"/>
      <mass value="4.05623"/>
      <inertia ixx="0.03204"  ixy="0"  ixz="0" iyy="0.00972" iyz="0.006227" izz="0.03042" />
    </inertial>
    
    <visual>
      <origin xyz="0 0 -0.026" rpy="0 0 0"/>
      <geometry>
        <mesh filename="meshes/visual/link_3.stl"/>
      </geometry>
      <material name="Orange">
        <color rgba="1.0 0.423529411765 0.0392156862745 1.0"/>
      </material>
    </visual>
    
    <collision>
      <origin xyz="0 0 -0.026" rpy="0 0 0"/>
      <geometry>
        <mesh filename="meshes/collision/link_3.stl"/>
      </geometry>
      <material name="Orange">
        <color rgba="1.0 0.423529411765 0.0392156862745 1.0"/>
      </material>
    </collision>
    
  </link>
    
  <joint name="iiwa7_joint_4" type="revolute">
    <parent link="iiwa7_link_3"/>
    <child link="iiwa7_link_4"/>
    <origin xyz="0 0 0.19" rpy="1.570796325 0 0"/>
    <axis xyz="0 0 1"/>
    <limit lower="-2.0944" upper="2.0944"
            effort="${max_effort}" velocity="${max_velocity}" />
    <safety_controller soft_lower_limit="${-118 * PI / 180}"
                        soft_upper_limit="${118 * PI / 180}"
                        k_position="${safety_controller_k_pos}"
                        k_velocity="${safety_controller_k_vel}"/> 
    <dynamics damping="${joint_damping}"/>
  </joint>
    
  <link name="iiwa7_link_4">
    <inertial>
      <origin xyz="0 0.067 0.034" rpy="0 0 0"/>
      <mass value="3.4822"/>
      <inertia ixx="0.02178"  ixy="0"  ixz="0" iyy="0.02075" iyz="-0.003625" izz="0.007785" />
    </inertial>
    
    <visual>
      <origin xyz="0 0 0" rpy="0 0 0"/>
      <geometry>
        <mesh filename="meshes/visual/link_4.stl"/>
      </geometry>
      <material name="Orange">
        <color rgba="1.0 0.423529411765 0.0392156862745 1.0"/>
      </material>
    </visual>
    
    <collision>
      <origin xyz="0 0 0" rpy="0 0 0"/>
      <geometry>
        <mesh filename="meshes/collision/link_4.stl"/>
      </geometry>
      <material name="Orange">
        <color rgba="1.0 0.423529411765 0.0392156862745 1.0"/>
      </material>
    </collision>
  </link>
    
  <joint name="iiwa7_joint_5" type="revolute">
    <parent link="iiwa7_link_4"/>
    <child link="iiwa7_link_5"/>
    <origin xyz="0 0.21 0" rpy="-1.570796325 3.1415926 0"/>
    <axis xyz="0 0 1"/>
    <limit lower="-2.96706" upper="2.96706"
            effort="${max_effort}" velocity="${max_velocity}" />
    <safety_controller soft_lower_limit="${-168 * PI / 180}"
                        soft_upper_limit="${168 * PI / 180}"
                        k_position="${safety_controller_k_pos}"
                        k_velocity="${safety_controller_k_vel}"/> 
    <dynamics damping="${joint_damping}"/>
  </joint>
    
  <link name="iiwa7_link_5">
    <inertial>
      <origin xyz="0.0001 0.021 0.076" rpy="0 0 0"/>
      <mass value="2.1633"/>
      <inertia ixx="0.01287"  ixy="0"  ixz="0" iyy="0.005708" iyz="-0.003946" izz="0.01112" />
    </inertial>
    
    <visual>
      <origin xyz="0 0 -0.026" rpy="0 0 0"/>
      <geometry>
        <mesh filename="meshes/visual/link_5.stl"/>
      </geometry>
      <material name="Orange">
        <color rgba="1.0 0.423529411765 0.0392156862745 1.0"/>
      </material>
    </visual>
    
    <collision>
      <origin xyz="0 0 -0.026" rpy="0 0 0"/>
      <geometry>
        <mesh filename="meshes/collision/link_5.stl"/>
      </geometry>
      <material name="Orange">
        <color rgba="1.0 0.423529411765 0.0392156862745 1.0"/>
      </material>
    </collision>
  </link>
    
  <joint name="iiwa7_joint_6" type="revolute">
    <parent link="iiwa7_link_5"/>
    <child link="iiwa7_link_6"/>
    <origin xyz="0 0.06070 0.19" rpy="1.570796325 0 0"/>
    <axis xyz="0 0 1"/>
    <limit lower="-2.0944" upper="2.0944"
            effort="${max_effort}" velocity="${max_velocity}" />
    <safety_controller soft_lower_limit="${-118 * PI / 180}"
                        soft_upper_limit="${118 * PI / 180}"
                        k_position="${safety_controller_k_pos}"
                        k_velocity="${safety_controller_k_vel}"/> 
    <dynamics damping="${joint_damping}"/>
  </joint>
    
  <link name="iiwa7_link_6">
    <inertial>
      <origin xyz="0 0.0006 0.0004" rpy="0 0 0"/>
      <mass value="2.3466"/>
      <inertia ixx="0.006509"  ixy="0"  ixz="0" iyy="0.006259" iyz="0.00031891" izz="0.004527" />
    </inertial>
    
    <visual>
      <origin xyz="0 0 0" rpy="0 0 0"/>
      <geometry>
        <mesh filename="meshes/visual/link_6.stl"/>
      </geometry>
      <material name="Orange">
        <color rgba="1.0 0.423529411765 0.0392156862745 1.0"/>
      </material>
    </visual>
    
    <collision>
      <origin xyz="0 0 0" rpy="0 0 0"/>
      <geometry>
        <mesh filename="meshes/collision/link_6.stl"/>
      </geometry>
      <material name="Orange">
        <color rgba="1.0 0.423529411765 0.0392156862745 1.0"/>
      </material>
    </collision>
  </link>
    
  <joint name="iiwa7_joint_7" type="revolute">
    <parent link="iiwa7_link_6"/>
    <child link="iiwa7_link_7"/>
    <origin xyz="0 0.081 0.06070" rpy="-1.570796325 3.1415926 0"/>
    <axis xyz="0 0 1"/>
    <limit lower="-3.05433" upper="3.05433"
            effort="${max_effort}" velocity="${max_velocity}" />
    <safety_controller soft_lower_limit="${-173 * PI / 180}"
                        soft_upper_limit="${173 * PI / 180}"
                        k_position="${safety_controller_k_pos}"
                        k_velocity="${safety_controller_k_vel}"/> 
    <dynamics damping="${joint_damping}"/>
  </joint>
    
  <link name="iiwa7_link_7">
    <inertial>
      <origin xyz="0 0 0.02" rpy="0 0 0"/>
      <mass value="3.129"/>
      <inertia ixx="0.01464"  ixy="0.0005912"  ixz="0" iyy="0.01465" iyz="0" izz="0.002872" />
    </inertial>
    
    <visual>
      <origin xyz="0 0 -0.0005" rpy="0 0 0"/>
      <geometry>
        <mesh filename="meshes/visual/link_7.stl"/>
      </geometry>
      <material name="Grey">
        <color rgba="0.4 0.4 0.4 1.0"/>
      </material>
    </visual>
    
    <collision>
      <origin xyz="0 0 -0.0005" rpy="0 0 0"/>
      <geometry>
        <mesh filename="meshes/collision/link_7.stl"/>
      </geometry>
      <material name="Grey">
        <color rgba="0.4 0.4 0.4 1.0"/>
      </material>
    </collision>
  </link>
    
  <joint name="iiwa7_right_hand_fixed" type="fixed">
    <parent link="iiwa7_link_7"/>
    <child link="iiwa7_right_hand"/>
    <origin xyz="0 0 0.044" rpy="0 0 0"/>
  </joint>
    
  <link name="iiwa7_right_hand">
    <inertial>
      <origin rpy="0 0 0" xyz="0 0 0"/>
      <mass value="0"/>
      <inertia ixx="0.0" ixy="0.0" ixz="0.0" iyy="0.0" iyz="0.0" izz="0.0"/>
    </inertial>
  </link>
</robot>
